
### 异常、断言

python提供了两个非常重要的功能来处理程序中的异常和错误，并在其中添加调试的函数功能

- 断言
- 异常处理



#### python 中的断言

断言是一个健全检查，可在完成对程序的测试后打开或关闭。

##### assert 语句

当遇到一个assert 语句时，会评估求值它的表达式，是否如所希望的那样。如果表达式为False，则会引发 ```AssertionError``` 异常。

><font color=red size =5>assert expression [, arg]</font>

<pre>
>>> assert 1 > 2   # 表达式 1 > 2 为 False，引发断言异常
Traceback (most recent call last):
  File "<pyshell#32>", line 1, in <module>
    assert 1 > 2
AssertionError
>>> assert 2 > 1
</pre>



#### 异常

在程序执行期间发生的破坏程序指令的正常流程的事件，一般来说，python脚本遇到无法应对的情况时，会引发异常。异常是一个表示错误的python对象。发生异常时，必须立即处理异常否则会终止并退出程序。

##### 处理异常

将可能出现异常的代码放在 try:块中来保护程序。在 try:块之后，包括一个 except: 语句，然后是一个尽可能描述清晰的处理问题的代码块。

<pre>
try:
    可能出现异常的代码块
except Exception1:
    发生异常Exception1时的处理方式
except Exception2:
    发生异常Exception2时的处理方式
else:
    无异常的处理逻辑
</pre>


- 一个 try 语句可以有多个 except 语句，当try包含的语句块引发不同类型的异常时，这就很有用了。
- 还可以提供一个通用的 except 字句处理任何异常。
- 在except语句之后，可以包含一个else语句，如果try：中的代码不引发异常，则else块中的代码将执行。
- else语句是一个不需要try语句保护的代码的地方。

示例：
<pre>
>>> try:
	assert 1 > 2
	1 /  0
	print(yourName)
except AssertionError:
    print("断言失败")
except ZeroDivisionError:
    print("0不能作为除数")
except:
    print("发生其他的异常")

    
断言失败


>>> try:
	#assert 1 > 2
	1 /  0
	print(yourName)
except AssertionError:
    print("断言失败")
except ZeroDivisionError:
    print("0不能作为除数")
except:
    print("发生其他的异常")

    
0不能作为除数


>>> try:
	#assert 1 > 2
	#1 /  0
	print(yourName)
except AssertionError:
    print("断言失败")
except ZeroDivisionError:
    print("0不能作为除数")
except:
    print("发生其他的异常")

    
发生其他的异常
</pre>


except 没有指定具体的异常则他会捕获所有的一场。



##### except 指定捕获多个异常

><font color=red size =5>except ( Exception1 [, Exception2...] )</font>

<pre>
>>> try:
	#assert 1 > 2
	1 /  0
	print(yourName)
except (AssertionError,ZeroDivisionError):
    print("断言失败 or 0不能作为除数")
except:
    print("发生其他的异常")

    
断言失败 or 0不能作为除数
</pre>

##### try-finally 子句

可以使用 finally 和 try 块。  finally块放置必须执行的代码，发生错误也会执行。

<pre>
try:
    可能发生异常的代码
finally:
    必须执行的代码（通常是关闭文件流的等操作）
</pre>


<pre>
>>> try:
	helloFile = open(r"C:\Users\Administrator\Desktop\python\pythonNote\hello.txt")   #只读模式打开文件
	helloFile.write("哈哈哈")   #写入文件发生异常
except:                        #捕获异常
	print("发生写文件错误")   
finally:                       #必须执行的代码
	helloFile.close()
	print("这是必须执行的代码")

	
发生写文件错误
这是必须执行的代码
</pre>

try 语句可以嵌套编写，  try里面包含try...



##### 异常参数
 一个异常可以有一个参数，参数是一个值，提供有关该问题的其他信息。参数的内容因异常而异。可以通过在 except 子句中提供变量来捕获异常的参数。

<pre>
try:
    可能产生异常的代码
except ExceptionType as arg:
    在这里可以打印异常参数 arg
    
</pre>

**变量可以以元组的形式接受单个值或多个值，该元组通常包含错误字符串、错误编号和错误位置**

实例如下：

<pre>
>>> try:
	1 / 0
except ZeroDivisionError as arg:
	print("0不能作为除数,详细信息为:", arg)

	
0不能作为除数,详细信息为: division by zero
</pre>



#### 抛出异常

可以使用<font color=red size =5> raise 语句</font> 来主动抛出异常。

>raise [Exception [, args] [, traceback]]
 
- Exception 是异常的类型（例如： NameError等）， args 是异常参数的值。 参数是可选的，如果没有提供，则异常参数为None。
- 最后一个参数 traceback 也是可选的，如果存在则是用于异常的追溯对象。

实例：
<pre>
>>> def func(arg):
	if arg < 1:
	    raise Exception(arg)
        #raise Exception
        #raise
	return arg

>>> func(2)
2
>>> func(0)
Traceback (most recent call last):
  File "<pyshell#278>", line 1, in <module>
    func(0)
  File "<pyshell#276>", line 3, in func
    raise Exception(arg)
Exception: 0
</pre>

#### 用户自定义异常

允许用户从标准内置异常导出类来创建自定义异常。


<pre>
>>> class MyError(RuntimeError):   # 自定义异常继承自RuntimeError
    def __init__(self, arg):
        self.args = arg

        
>>> try:
    raise MyError("这是自定义异常!")
except MyError as e:
    print(e.args)

    
('这', '是', '自', '定', '义', '异', '常', '!')
</pre>

